Workbook

Sheet Leeme
A1: Malla SALVIA Etapa 2 | B1: Actualizada el 28 de octubre de 2026 (horas de gerencia de octubre en Bolsa 2 y plan de cierre a diciembre). Versión anterior: 27 de octubre de 2026.
A2: Hitos | B2: Los hitos de producto siguen los módulos del Anexo Técnico: M1 Seguimiento, M2 Tamizaje de feminicidio, M3 Medidas de Emergencia (nuevo), M4 LGBTIQ+, M5 ASP y la app móvil. Los hitos transversales H06 a H11 no cambian. La hoja Hitos trae el ID anterior de cada uno.
A3: Entendimiento | B3: Se agregaron a la EDT los grupos 4.4 (Reporte y Registro) y 4.5 (Medidas de Emergencia), más las filas de construcción 6.1.8 a 6.1.10 y de pruebas 7.1.7. Reporte y Registro cruza con M2, M4 y M5 porque sus preguntas de identificación de la víctima cubren tamizaje, LGBTIQ+ y ASP. Actas separa el avance de cada hito en entendimiento (obligaciones 1 a 4) y construcción y cierre (obligaciones 5 a 13).
A4: Qué se edita | B4: Solo la columna Avance_% de las actividades de tercer nivel en la hoja Plan (celdas amarillas) y los textos de la hoja Actas. Todo lo demás se calcula.
A5: Estados | B5: Pendiente = 0 %. En curso = entre 1 % y 99 %. Completado = 100 %. Las filas de primer y segundo nivel promedian sus actividades.
A6: Matriz | B6: Ya no es 0/1: muestra 0 si la actividad no pertenece al hito, 1 pendiente, 2 en curso, 3 completado. La pertenencia original está en la hoja Pertenencia.
A7: Avance del hito | B7: Promedio del avance de las actividades de tercer nivel que pertenecen al hito. Reemplaza los porcentajes puestos a mano en julio, que se conservan en la columna Avance_julio de Actas; por el cambio de método no son comparables uno a uno.
A8: Avance EDT | B8: Promedio de las 103 actividades de tercer nivel. El generador lo calcula y lo escribe en el encabezado del tablero.
A9: Evidencia y confianza | B9: Cada actividad cita su soporte. Alta: consta en documentos revisados. Media: inferido de ellos. Por confirmar: sin soporte en lo revisado.
A10: Fuentes | B10: Solicitud de prórroga (22-sep), informe de alcance y riesgos (17-sep), mapa mental de agosto, Anexo Técnico, historias de usuario de Medidas de Emergencia v1.0, guía del mockup de Reporte y Registro (27-sep), bitácora de ajustes (1-oct), Sprints 15 a 19, commits de septiembre y fichas de julio.
A11: Antes de generar | B11: Abrir y guardar este archivo en Excel si se cambió algún avance, para que las fórmulas queden calculadas; luego correr generador_registry.py.
A12: Navegación mensual | B12: El tablero muestra cada mes de febrero a septiembre y el corte del 6-oct. La hoja Meses trae las horas oficiales por bolsa y los aspectos relevantes de cada resumen; Fichas_Mes, el texto de cada hito por mes (tomado de los resúmenes mensuales). El corte de octubre usa los textos de Actas.
... A24: Riesgos_QA | B24: Hallazgos de QA con fecha de detección y de cierre. El dashboard marca con ⚠ un hito cuando, al corte del mes seleccionado, tiene hallazgos con Critico = Sí (severidad Crítica o Alta) abiertos: detectados antes del corte y sin cerrar, o cerrados después del corte. Los cerrados sin fecha en la matriz toman la fecha de la revisión Kreivo (8-oct-2026). Celdas amarillas editables.

Sheet Plan
A1: ID | B1: Actividad | C1: ENTREGABLE | D1: Nivel | E1: Avance_% | F1: Estado | G1: Evidencia al 28-oct-2026 | H1: Confianza | I1: Codigo_Estado | J1: Fase
A2: 1 | B2: OBL-01: APROBACION EQUIPO DE TRABAJO | C2: Hojas de vida, soportes academicos y certificados de proyectos aprobados por el Ministerio | D2: 1 | E2: =SUMPRODUCT((D3:D5=3)*E3:E5)/COUNTIF(D3:D5,3) -> 1 | F2: =IF(E2>=0.995,"Completado",IF(E2>0,"En curso","Pendiente")) -> Completado | I2: =IF(E2>=0.995,3,IF(E2>0,2,1)) -> 3 | J2: Entendimiento
A3: 1.1 | B3: Conformacion y validacion del equipo (Bolsa 1) | C3: Equipo Bolsa 1 conformado y aprobado | D3: 2 | E3: =SUMPRODUCT((D4:D5=3)*E4:E5)/COUNTIF(D4:D5,3) -> 1 | F3: =IF(E3>=0.995,"Completado",IF(E3>0,"En curso","Pendiente")) -> Completado | I3: =IF(E3>=0.995,3,IF(E3>0,2,1)) -> 3 | J3: Entendimiento
A4: 1.1.1 | B4: Entrega de hojas de vida y soportes del equipo | C4: HV, soportes academicos y certificados entregados | D4: 3 | E4: 1 | F4: =IF(E4>=0.995,"Completado",IF(E4>0,"En curso","Pendiente")) -> Completado | G4: El equipo opera desde febrero; sin acta de aprobación en los documentos revisados | H4: Media | I4: =IF(E4>=0.995,3,IF(E4>0,2,1)) -> 3 | J4: Entendimiento
A5: 1.1.2 | B5: Reunion de inicio y presentacion del proyecto | C5: Acta de reunion de inicio | D5: 3 | E5: 1 | F5: =IF(E5>=0.995,"Completado",IF(E5>0,"En curso","Pendiente")) -> Completado | G5: Acta de inicio del 26-ene-2026, citada en la solicitud de prórroga | H5: Alta | I5: =IF(E5>=0.995,3,IF(E5>0,2,1)) -> 3 | J5: Entendimiento
A6: 2 | B6: OBL-02: PLAN DE GESTION DEL PROYECTO | C6: Plan de gestion, cronograma, plan de comunicaciones, gestion del cambio, plan de QA y matriz de riesgos | D6: 1 | E6: =SUMPRODUCT((D7:D15=3)*E7:E15)/COUNTIF(D7:D15,3) -> 0.77142857 | F6: =IF(E6>=0.995,"Completado",IF(E6>0,"En curso","Pendiente")) -> En curso | I6: =IF(E6>=0.995,3,IF(E6>0,2,1)) -> 2 | J6: Entendimiento
A7: 2.1 | B7: Gestion integral del proyecto SALVIA Web (Bolsa 1) | C7: Artefactos de gestion de la Bolsa 1 aprobados | D7: 2 | E7: =SUMPRODUCT((D8:D11=3)*E8:E11)/COUNTIF(D8:D11,3) -> 0.85 | F7: =IF(E7>=0.995,"Completado",IF(E7>0,"En curso","Pendiente")) -> En curso | I7: =IF(E7>=0.995,3,IF(E7>0,2,1)) -> 2 | J7: Entendimiento
A8: 2.1.1 | B8: Presentacion, aprobacion y uso del Mockup Kreivo-SALVIA | C8: Mockup v2.4-v3.4 aprobado por el Ministerio | D8: 3 | E8: 1 | F8: =IF(E8>=0.995,"Completado",IF(E8>0,"En curso","Pendiente")) -> Completado | G8: Ficha de julio: mockups v2.4 a v3.4 validados | H8: Media | I8: =IF(E8>=0.995,3,IF(E8>0,2,1)) -> 3 | J8: Entendimiento
A9: 2.1.2 | B9: Firma de Acta de Alcance y SLA | C9: Acta de alcance y SLA firmada | D9: 3 | E9: 0.9 | F9: =IF(E9>=0.995,"Completado",IF(E9>0,"En curso","Pendiente")) -> En curso | G9: Prórroga del contrato otorgada hasta el 31-dic-2026; queda pendiente el acta formal del nuevo alcance | H9: Media | I9: =IF(E9>=0.995,3,IF(E9>0,2,1)) -> 2 | J9: Entendimiento
A10: 2.1.3 | B10: Levantamiento: Modulo Web ASP - Variables de Riesgo | C10: Documento de variables de riesgo ASP | D10: 3 | E10: 0.5 | F10: =IF(E10>=0.995,"Completado",IF(E10>0,"En curso","Pendiente")) -> En curso | G10: Variables de riesgo documentadas en julio. Lineamientos, mockups y criterios de la Dirección ASP no recibidos | H10: Media | I10: =IF(E10>=0.995,3,IF(E10>0,2,1)) -> 2 | J10: Entendimiento
A11: 2.1.4 | B11: Gantt y plan de trabajo Kreivo-SALVIA | C11: Cronograma Gantt aprobado | D11: 3 | E11: 1 | F11: =IF(E11>=0.995,"Completado",IF(E11>0,"En curso","Pendiente")) -> Completado | G11: Gantt aprobado en julio y ajustado a la prórroga hasta el 31-dic: plan de cierre de 8 semanas con 12 líneas, responsables y semanas (hoja Plan_Cierre, 28-oct) | H11: Alta | I11: =IF(E11>=0.995,3,IF(E11>0,2,1)) -> 3 | J11: Entendimiento
A12: 2.2 | B12: Gestion integral del proyecto App MASP (Bolsa 2) | C12: Artefactos de gestion de la Bolsa 2 aprobados | D12: 2 | E12: =SUMPRODUCT((D13:D15=3)*E13:E15)/COUNTIF(D13:D15,3) -> 0.66666667 | F12: =IF(E12>=0.995,"Completado",IF(E12>0,"En curso","Pendiente")) -> En curso | I12: =IF(E12>=0.995,3,IF(E12>0,2,1)) -> 2 | J12: Entendimiento
A13: 2.2.1 | B13: App MASP: diseno de interfaz segura | C13: Documento de UX/UI de interfaz segura | D13: 3 | E13: 1 | F13: =IF(E13>=0.995,"Completado",IF(E13>0,"En curso","Pendiente")) -> Completado | G13: Rediseño de la app entregado el 16-sep | H13: Media | I13: =IF(E13>=0.995,3,IF(E13>0,2,1)) -> 3 | J13: Entendimiento
A14: 2.2.2 | B14: App MASP: diseno de alertas y Push Notifications | C14: Especificacion de alertas y notificaciones push | D14: 3 | E14: 0.75 | F14: =IF(E14>=0.995,"Completado",IF(E14>0,"En curso","Pendiente")) -> En curso | G14: Informe 17-sep: Seguridad y SOS completado; sincronización y bitácora en desarrollo | H14: Media | I14: =IF(E14>=0.995,3,IF(E14>0,2,1)) -> 2 | J14: Entendimiento
A15: 2.2.3 | B15: App MASP: integracion con core SALVIA | C15: Especificacion de integracion API App-Core | D15: 3 | E15: 0.25 | F15: =IF(E15>=0.995,"Completado",IF(E15>0,"En curso","Pendiente")) -> En curso | G15: Integración app-web prevista para octubre; el desarrollo integral de ASP no es viable en la prórroga | H15: Alta | I15: =IF(E15>=0.995,3,IF(E15>0,2,1)) -> 2 | J15: Entendimiento
A16: 3 | B16: OBL-03: METODOLOGIA DE DESARROLLO DE SOFTWARE | C16: Documento metodologico (Planificacion, Diseno, QA, Lanzamiento, Mantenimiento) | D16: 1 | E16: =SUMPRODUCT((D17:D23=3)*E17:E23)/COUNTIF(D17:D23,3) -> 0.81 | F16: =IF(E16>=0.995,"Completado",IF(E16>0,"En curso","Pendiente")) -> En curso | I16: =IF(E16>=0.995,3,IF(E16>0,2,1)) -> 2 | J16: Entendimiento
A17: 3.1 | B17: Metodologia de desarrollo - SALVIA Web (Bolsa 1) | C17: Metodologia documentada y aprobada para modulos web | D17: 2 | E17: =SUMPRODUCT((D18:D20=3)*E18:E20)/COUNTIF(D18:D20,3) -> 0.85 | F17: =IF(E17>=0.995,"Completado",IF(E17>0,"En curso","Pendiente")) -> En curso | I17: =IF(E17>=0.995,3,IF(E17>0,2,1)) -> 2 | J17: Entendimiento
A18: 3.1.1 | B18: Diseno y logica: Landing Page, Login y Captcha | C18: Pantallas y logica aprobadas | D18: 3 | E18: 1 | F18: =IF(E18>=0.995,"Completado",IF(E18>0,"En curso","Pendiente")) -> Completado | G18: En producción. Hay un rediseño del login en rama de diseño, sin integrar | H18: Alta | I18: =IF(E18>=0.995,3,IF(E18>0,2,1)) -> 3 | J18: Entendimiento
A19: 3.1.2 | B19: Logica y arbol de decision: Modulo de Tamizaje (escala severidad) | C19: Arbol de decision aprobado | D19: 3 | E19: 0.65 | F19: =IF(E19>=0.995,"Completado",IF(E19>0,"En curso","Pendiente")) -> En curso | G19: Clasificación alto/bajo y tiempos por riesgo operan; el árbol de tamizaje ya se calcula desde el Registro V3 en testing (casos TZ del plan de QA). Falta calibrar rangos con el Ministerio | H19: Alta | I19: =IF(E19>=0.995,3,IF(E19>0,2,1)) -> 2 | J19: Entendimiento
A20: 3.1.3 | B20: Refinamiento UX: Dashboard y trazabilidad de casos | C20: UX final de dashboard y trazabilidad | D20: 3 | E20: 0.9 | F20: =IF(E20>=0.995,"Completado",IF(E20>0,"En curso","Pendiente")) -> En curso | G20: Corte 13-oct más, en testing: estados de caso que la lista mostraba como Desconocido, con filtro por estado (4f9b633), y casos registrados que quedan con estado (1dee9b9) | H20: Alta | I20: =IF(E20>=0.995,3,IF(E20>0,2,1)) -> 2 | J20: Entendimiento
A21: 3.2 | B21: Metodologia de desarrollo - App MASP (Bolsa 2) | C21: Metodologia documentada y aprobada para app movil | D21: 2 | E21: =SUMPRODUCT((D22:D23=3)*E22:E23)/COUNTIF(D22:D23,3) -> 0.75 | F21: =IF(E21>=0.995,"Completado",IF(E21>0,"En curso","Pendiente")) -> En curso | I21: =IF(E21>=0.995,3,IF(E21>0,2,1)) -> 2 | J21: Entendimiento
A22: 3.2.1 | B22: Diseno de flujos y UI: App Movil MASP | C22: Flujos y UI aprobados | D22: 3 | E22: 1 | F22: =IF(E22>=0.995,"Completado",IF(E22>0,"En curso","Pendiente")) -> Completado | G22: Flujos y pantallas de la app definidos; la prórroga no incluye pantallas nuevas | H22: Media | I22: =IF(E22>=0.995,3,IF(E22>0,2,1)) -> 3 | J22: Entendimiento
A23: 3.2.2 | B23: Aprobacion de Arquitectura e Interoperabilidad | C23: Documento de arquitectura de interoperabilidad aprobado | D23: 3 | E23: 0.5 | F23: =IF(E23>=0.995,"Completado",IF(E23>0,"En curso","Pendiente")) -> En curso | G23: Arquitectura aprobada; mecanismo de interoperabilidad con SIVIGE sin definir | H23: Alta | I23: =IF(E23>=0.995,3,IF(E23>0,2,1)) -> 2 | J23: Entendimiento
A24: 4 | B24: OBL-04: ANALISIS, DISENO Y REQUERIMIENTOS | C24: Arquitectura, casos de uso, diccionario de datos, diagramas, actas de mesas tecnicas e historias de usuario | D24: 1 | E24: =SUMPRODUCT((D25:D54=3)*E25:E54)/COUNTIF(D25:D54,3) -> 0.806 | F24: =IF(E24>=0.995,"Completado",IF(E24>0,"En curso","Pendiente")) -> En curso | I24: =IF(E24>=0.995,3,IF(E24>0,2,1)) -> 2 | J24: Entendimiento
A25: 4.1 | B25: Documentacion previa y auditoria (Bolsa 1) | C25: Documentacion de la etapa 1 consolidada | D25: 2 | E25: =SUMPRODUCT((D26:D28=3)*E26:E28)/COUNTIF(D26:D28,3) -> 1 | F25: =IF(E25>=0.995,"Completado",IF(E25>0,"En curso","Pendiente")) -> Completado | I25: =IF(E25>=0.995,3,IF(E25>0,2,1)) -> 3 | J25: Entendimiento
A26: 4.1.1 | B26: Documentacion y metodologia SALVIA Web heredada | C26: Informe de documentacion SALVIA Web | D26: 3 | E26: 1 | F26: =IF(E26>=0.995,"Completado",IF(E26>0,"En curso","Pendiente")) -> Completado | G26: Fase inicial cerrada (hito de arquitectura al 100 % en julio) | H26: Media | I26: =IF(E26>=0.995,3,IF(E26>0,2,1)) -> 3 | J26: Entendimiento
A27: 4.1.2 | B27: Historias de Usuario actuales (sistema heredado) | C27: Inventario de HU existentes | D27: 3 | E27: 1 | F27: =IF(E27>=0.995,"Completado",IF(E27>0,"En curso","Pendiente")) -> Completado | G27: Fase inicial cerrada | H27: Media | I27: =IF(E27>=0.995,3,IF(E27>0,2,1)) -> 3 | J27: Entendimiento
A28: 4.1.3 | B28: Arquitectura actual y diagnostico de deuda tecnica | C28: Informe de arquitectura actual | D28: 3 | E28: 1 | F28: =IF(E28>=0.995,"Completado",IF(E28>0,"En curso","Pendiente")) -> Completado | G28: Fase inicial cerrada | H28: Media | I28: =IF(E28>=0.995,3,IF(E28>0,2,1)) -> 3 | J28: Entendimiento
A29: 4.2 | B29: Analisis y diseno SALVIA Web (Bolsa 1) | C29: Artefactos de analisis y diseno aprobados | D29: 2 | E29: =SUMPRODUCT((D30:D37=3)*E30:E37)/COUNTIF(D30:D37,3) -> 0.8 | F29: =IF(E29>=0.995,"Completado",IF(E29>0,"En curso","Pendiente")) -> En curso | I29: =IF(E29>=0.995,3,IF(E29>0,2,1)) -> 2 | J29: Entendimiento
A30: 4.2.1 | B30: Arquitectura SOG hacia EAV-DAG | C30: Diseno de arquitectura EAV-DAG | D30: 3 | E30: 1 | F30: =IF(E30>=0.995,"Completado",IF(E30>0,"En curso","Pendiente")) -> Completado | G30: Arquitectura EAV-DAG implementada y en producción | H30: Alta | I30: =IF(E30>=0.995,3,IF(E30>0,2,1)) -> 3 | J30: Entendimiento
A31: 4.2.2 | B31: Casos de uso e Historias de Usuario (interconectividad y flujo) | C31: Casos de uso e HU integrados | D31: 3 | E31: 0.85 | F31: =IF(E31>=0.995,"Completado",IF(E31>0,"En curso","Pendiente")) -> En curso | G31: Historias de usuario en curso (PSWYA-778, Medidas) y formulario de seguimiento V4 con prototipo, siembra y lógica (PSWYA-871 a 878, octubre) | H31: Alta | I31: =IF(E31>=0.995,3,IF(E31>0,2,1)) -> 2 | J31: Entendimiento
A32: 4.2.3 | B32: Diagramas Figma y diccionario de datos (SALVIA Web) | C32: Diagramas Figma y diccionario de datos | D32: 3 | E32: 0.75 | F32: =IF(E32>=0.995,"Completado",IF(E32>0,"En curso","Pendiente")) -> En curso | G32: Diccionario preliminar entregado; mockups de Medidas, Familiares y LGBTIQ+ por aprobar | H32: Media | I32: =IF(E32>=0.995,3,IF(E32>0,2,1)) -> 2 | J32: Entendimiento
A33: 4.2.4 | B33: Actas de mesas tecnicas | C33: Actas de mesas tecnicas firmadas | D33: 3 | E33: 0.9 | F33: =IF(E33>=0.995,"Completado",IF(E33>0,"En curso","Pendiente")) -> En curso | G33: Mesas técnicas continuas; últimas el 30-sep (cuatro sesiones) | H33: Alta | I33: =IF(E33>=0.995,3,IF(E33>0,2,1)) -> 2 | J33: Entendimiento
A34: 4.2.5 | B34: Historias de Usuario ancladas a Figma | C34: HU vinculadas a Figma | D34: 3 | E34: 0.6 | F34: =IF(E34>=0.995,"Completado",IF(E34>0,"En curso","Pendiente")) -> En curso | G34: Depende de los mockups pendientes de aprobación | H34: Media | I34: =IF(E34>=0.995,3,IF(E34>0,2,1)) -> 2 | J34: Entendimiento
A35: 4.2.6 | B35: Migracion de Kobo a Zenkit (analisis solucion transitoria) | C35: Zenkit desplegado y operativo | D35: 3 | E35: 1 | F35: =IF(E35>=0.995,"Completado",IF(E35>0,"En curso","Pendiente")) -> Completado | G35: Ficha de julio: solución transitoria Zenkit desplegada | H35: Media | I35: =IF(E35>=0.995,3,IF(E35>0,2,1)) -> 3 | J35: Entendimiento
A36: 4.2.7 | B36: Integracion data SOG hacia EAV-DAG | C36: Scripts de integracion ejecutados | D36: 3 | E36: 0.8 | F36: =IF(E36>=0.995,"Completado",IF(E36>0,"En curso","Pendiente")) -> En curso | G36: Migración ejecutada; quedan casos migrados con formularios vacíos o sin esquema (SEG-01, SEG-02) | H36: Alta | I36: =IF(E36>=0.995,3,IF(E36>0,2,1)) -> 2 | J36: Entendimiento
A37: 4.2.8 | B37: Documentacion y metodologia App MASP | C37: Informe de documentacion App MASP | D37: 3 | E37: 0.5 | F37: =IF(E37>=0.995,"Completado",IF(E37>0,"En curso","Pendiente")) -> En curso | G37: Sin evidencia en los documentos revisados | H37: Por confirmar | I37: =IF(E37>=0.995,3,IF(E37>0,2,1)) -> 2 | J37: Entendimiento
A38: 4.3 | B38: Analisis y diseno App MASP (Bolsa 2) | C38: Artefactos de analisis y diseno de la App aprobados | D38: 2 | E38: =SUMPRODUCT((D39:D39=3)*E39:E39)/COUNTIF(D39:D39,3) -> 0.6 | F38: =IF(E38>=0.995,"Completado",IF(E38>0,"En curso","Pendiente")) -> En curso | I38: =IF(E38>=0.995,3,IF(E38>0,2,1)) -> 2 | J38: Entendimiento
A39: 4.3.1 | B39: Diagramas Figma y diccionario de datos (App MASP) | C39: Diagramas Figma y diccionario de datos App | D39: 3 | E39: 0.6 | F39: =IF(E39>=0.995,"Completado",IF(E39>0,"En curso","Pendiente")) -> En curso | G39: Rediseño hecho; diccionario de datos de la app sin evidencia | H39: Por confirmar | I39: =IF(E39>=0.995,3,IF(E39>0,2,1)) -> 2 | J39: Entendimiento
A40: 4.4 | B40: Entendimiento: Reporte y Registro (Bolsa 1) | C40: Guion, formulario y mockup de Reporte y Registro validados | D40: 2 | E40: =SUMPRODUCT((D41:D48=3)*E41:E48)/COUNTIF(D41:D48,3) -> 0.9375 | F40: =IF(E40>=0.995,"Completado",IF(E40>0,"En curso","Pendiente")) -> En curso | I40: =IF(E40>=0.995,3,IF(E40>0,2,1)) -> 2 | J40: Entendimiento
...

Sheet Matriz
A1: ID | B1: M1 | C1: M2 | D1: M3 | E1: M4 | F1: M5 | G1: APP | H1: H06 | I1: H07 | J1: H08 | K1: H09 | L1: H10 | M1: H11
A2: 1 | B2: =IF(Pertenencia!B2=1,Plan!$I2,0) -> 0 | C2: =IF(Pertenencia!C2=1,Plan!$I2,0) -> 0 | D2: =IF(Pertenencia!D2=1,Plan!$I2,0) -> 0 | E2: =IF(Pertenencia!E2=1,Plan!$I2,0) -> 0 | F2: =IF(Pertenencia!F2=1,Plan!$I2,0) -> 0 | G2: =IF(Pertenencia!G2=1,Plan!$I2,0) -> 0 | H2: =IF(Pertenencia!H2=1,Plan!$I2,0) -> 0 | I2: =IF(Pertenencia!I2=1,Plan!$I2,0) -> 3 | ... M2: =IF(Pertenencia!M2=1,Plan!$I2,0) -> 0
A3: 1.1 | B3: =IF(Pertenencia!B3=1,Plan!$I3,0) -> 0 | C3: =IF(Pertenencia!C3=1,Plan!$I3,0) -> 0 | D3: =IF(Pertenencia!D3=1,Plan!$I3,0) -> 0 | E3: =IF(Pertenencia!E3=1,Plan!$I3,0) -> 0 | F3: =IF(Pertenencia!F3=1,Plan!$I3,0) -> 0 | G3: =IF(Pertenencia!G3=1,Plan!$I3,0) -> 0 | H3: =IF(Pertenencia!H3=1,Plan!$I3,0) -> 0 | I3: =IF(Pertenencia!I3=1,Plan!$I3,0) -> 3 | ... M3: =IF(Pertenencia!M3=1,Plan!$I3,0) -> 0
A4: 1.1.1 | B4: =IF(Pertenencia!B4=1,Plan!$I4,0) -> 0 | C4: =IF(Pertenencia!C4=1,Plan!$I4,0) -> 0 | D4: =IF(Pertenencia!D4=1,Plan!$I4,0) -> 0 | E4: =IF(Pertenencia!E4=1,Plan!$I4,0) -> 0 | F4: =IF(Pertenencia!F4=1,Plan!$I4,0) -> 0 | G4: =IF(Pertenencia!G4=1,Plan!$I4,0) -> 0 | H4: =IF(Pertenencia!H4=1,Plan!$I4,0) -> 0 | I4: =IF(Pertenencia!I4=1,Plan!$I4,0) -> 3 | ... M4: =IF(Pertenencia!M4=1,Plan!$I4,0) -> 0
A5: 1.1.2 | B5: =IF(Pertenencia!B5=1,Plan!$I5,0) -> 0 | C5: =IF(Pertenencia!C5=1,Plan!$I5,0) -> 0 | D5: =IF(Pertenencia!D5=1,Plan!$I5,0) -> 0 | E5: =IF(Pertenencia!E5=1,Plan!$I5,0) -> 0 | F5: =IF(Pertenencia!F5=1,Plan!$I5,0) -> 0 | G5: =IF(Pertenencia!G5=1,Plan!$I5,0) -> 0 | H5: =IF(Pertenencia!H5=1,Plan!$I5,0) -> 0 | I5: =IF(Pertenencia!I5=1,Plan!$I5,0) -> 3 | ... M5: =IF(Pertenencia!M5=1,Plan!$I5,0) -> 0
A6: 2 | B6: =IF(Pertenencia!B6=1,Plan!$I6,0) -> 0 | C6: =IF(Pertenencia!C6=1,Plan!$I6,0) -> 0 | D6: =IF(Pertenencia!D6=1,Plan!$I6,0) -> 0 | E6: =IF(Pertenencia!E6=1,Plan!$I6,0) -> 0 | F6: =IF(Pertenencia!F6=1,Plan!$I6,0) -> 2 | G6: =IF(Pertenencia!G6=1,Plan!$I6,0) -> 2 | H6: =IF(Pertenencia!H6=1,Plan!$I6,0) -> 2 | I6: =IF(Pertenencia!I6=1,Plan!$I6,0) -> 2 | ... M6: =IF(Pertenencia!M6=1,Plan!$I6,0) -> 0
A7: 2.1 | B7: =IF(Pertenencia!B7=1,Plan!$I7,0) -> 0 | C7: =IF(Pertenencia!C7=1,Plan!$I7,0) -> 0 | D7: =IF(Pertenencia!D7=1,Plan!$I7,0) -> 0 | E7: =IF(Pertenencia!E7=1,Plan!$I7,0) -> 0 | F7: =IF(Pertenencia!F7=1,Plan!$I7,0) -> 2 | G7: =IF(Pertenencia!G7=1,Plan!$I7,0) -> 0 | H7: =IF(Pertenencia!H7=1,Plan!$I7,0) -> 2 | I7: =IF(Pertenencia!I7=1,Plan!$I7,0) -> 2 | ... M7: =IF(Pertenencia!M7=1,Plan!$I7,0) -> 0
A8: 2.1.1 | B8: =IF(Pertenencia!B8=1,Plan!$I8,0) -> 0 | C8: =IF(Pertenencia!C8=1,Plan!$I8,0) -> 0 | D8: =IF(Pertenencia!D8=1,Plan!$I8,0) -> 0 | E8: =IF(Pertenencia!E8=1,Plan!$I8,0) -> 0 | F8: =IF(Pertenencia!F8=1,Plan!$I8,0) -> 0 | G8: =IF(Pertenencia!G8=1,Plan!$I8,0) -> 0 | H8: =IF(Pertenencia!H8=1,Plan!$I8,0) -> 3 | I8: =IF(Pertenencia!I8=1,Plan!$I8,0) -> 3 | ... M8: =IF(Pertenencia!M8=1,Plan!$I8,0) -> 0
A9: 2.1.2 | B9: =IF(Pertenencia!B9=1,Plan!$I9,0) -> 0 | C9: =IF(Pertenencia!C9=1,Plan!$I9,0) -> 0 | D9: =IF(Pertenencia!D9=1,Plan!$I9,0) -> 0 | E9: =IF(Pertenencia!E9=1,Plan!$I9,0) -> 0 | F9: =IF(Pertenencia!F9=1,Plan!$I9,0) -> 0 | G9: =IF(Pertenencia!G9=1,Plan!$I9,0) -> 0 | H9: =IF(Pertenencia!H9=1,Plan!$I9,0) -> 0 | I9: =IF(Pertenencia!I9=1,Plan!$I9,0) -> 2 | ... M9: =IF(Pertenencia!M9=1,Plan!$I9,0) -> 0
A10: 2.1.3 | B10: =IF(Pertenencia!B10=1,Plan!$I10,0) -> 0 | C10: =IF(Pertenencia!C10=1,Plan!$I10,0) -> 0 | D10: =IF(Pertenencia!D10=1,Plan!$I10,0) -> 0 | E10: =IF(Pertenencia!E10=1,Plan!$I10,0) -> 0 | F10: =IF(Pertenencia!F10=1,Plan!$I10,0) -> 2 | G10: =IF(Pertenencia!G10=1,Plan!$I10,0) -> 0 | H10: =IF(Pertenencia!H10=1,Plan!$I10,0) -> 0 | I10: =IF(Pertenencia!I10=1,Plan!$I10,0) -> 2 | ... M10: =IF(Pertenencia!M10=1,Plan!$I10,0) -> 0
A11: 2.1.4 | B11: =IF(Pertenencia!B11=1,Plan!$I11,0) -> 0 | C11: =IF(Pertenencia!C11=1,Plan!$I11,0) -> 0 | D11: =IF(Pertenencia!D11=1,Plan!$I11,0) -> 0 | E11: =IF(Pertenencia!E11=1,Plan!$I11,0) -> 0 | F11: =IF(Pertenencia!F11=1,Plan!$I11,0) -> 0 | G11: =IF(Pertenencia!G11=1,Plan!$I11,0) -> 0 | H11: =IF(Pertenencia!H11=1,Plan!$I11,0) -> 0 | I11: =IF(Pertenencia!I11=1,Plan!$I11,0) -> 3 | ... M11: =IF(Pertenencia!M11=1,Plan!$I11,0) -> 0
A12: 2.2 | B12: =IF(Pertenencia!B12=1,Plan!$I12,0) -> 0 | C12: =IF(Pertenencia!C12=1,Plan!$I12,0) -> 0 | D12: =IF(Pertenencia!D12=1,Plan!$I12,0) -> 0 | E12: =IF(Pertenencia!E12=1,Plan!$I12,0) -> 0 | F12: =IF(Pertenencia!F12=1,Plan!$I12,0) -> 2 | G12: =IF(Pertenencia!G12=1,Plan!$I12,0) -> 2 | H12: =IF(Pertenencia!H12=1,Plan!$I12,0) -> 0 | I12: =IF(Pertenencia!I12=1,Plan!$I12,0) -> 0 | ... M12: =IF(Pertenencia!M12=1,Plan!$I12,0) -> 0
A13: 2.2.1 | B13: =IF(Pertenencia!B13=1,Plan!$I13,0) -> 0 | C13: =IF(Pertenencia!C13=1,Plan!$I13,0) -> 0 | D13: =IF(Pertenencia!D13=1,Plan!$I13,0) -> 0 | E13: =IF(Pertenencia!E13=1,Plan!$I13,0) -> 0 | F13: =IF(Pertenencia!F13=1,Plan!$I13,0) -> 0 | G13: =IF(Pertenencia!G13=1,Plan!$I13,0) -> 3 | H13: =IF(Pertenencia!H13=1,Plan!$I13,0) -> 0 | I13: =IF(Pertenencia!I13=1,Plan!$I13,0) -> 0 | ... M13: =IF(Pertenencia!M13=1,Plan!$I13,0) -> 0
... A145: 13.2.1 | B145: =IF(Pertenencia!B145=1,Plan!$I145,0) -> 0 | C145: =IF(Pertenencia!C145=1,Plan!$I145,0) -> 0 | D145: =IF(Pertenencia!D145=1,Plan!$I145,0) -> 0 | E145: =IF(Pertenencia!E145=1,Plan!$I145,0) -> 0 | F145: =IF(Pertenencia!F145=1,Plan!$I145,0) -> 0 | G145: =IF(Pertenencia!G145=1,Plan!$I145,0) -> 0 | H145: =IF(Pertenencia!H145=1,Plan!$I145,0) -> 0 | I145: =IF(Pertenencia!I145=1,Plan!$I145,0) -> 2 | ... M145: =IF(Pertenencia!M145=1,Plan!$I145,0) -> 0

Sheet Actas
A1: ID_Hito | B1: Nombre_Hito | C1: Fecha_Ejecucion | D1: Avance_% | E1: Resumen_Acta (Ficha Técnica) | F1: Responsable | G1: Avance_julio | H1: Fecha_Corte | I1: Avance_Entendimiento | J1: Avance_Construccion | K1: Grupo
A2: M1 | B2: M1 · SEGUIMIENTO A LOS CASOS | C2: 46191 | D2: =SUMPRODUCT((Pertenencia!B$2:B$145=1)*(Plan!$D$2:$D$145=3)*Plan!$E$2:$E$145)/SUMPRODUCT((Pertenencia!B$2:B$145=1)*(Plan!$D$2:$D$145=3)) -> 0.75 | E2: Corte 23-oct: en testing quedaron 29 commits más. Rutas y gestión institucional suma la migración de las Alcaldías y de 38 entidades con sus acciones institucionales, el DIVIPOLA y las sedes desde el Directorio, y corrige lo que la supervisión reportó del rol entidad (sede del usuario, cerrar sesión, Mis Tareas, estilos, sucursal). Psicosocial y Seguimiento suman indicador de atenciones, filtro por dupla y fechas sin bloqueo; el formulario de seguimiento V4 tiene prototipo y siembra en base. Avance: Seguimiento, Barreras, Notificaciones, Tareas y Atención Psicosocial están en producción; Rutas y gestión institucional está en pruebas. El equipo dejó listos 64 cambios para el próximo despliegue a main (corte 13-oct): Rutas y gestión institucional (Mis Acciones Institucionales, Casos Entidad y Mecanismo, checklist de obligaciones, catálogo de competencias y carga masiva del directorio), Atención Psicosocial (cierre y validación de remisiones, contacto inmediato, filtro por dupla) y Seguimiento (vencidos, zona horaria, reapertura por supervisor). Varios de estos cambios corrigen hallazgos que la matriz de SALVIA aún marcaba abiertos porque no se habían reportado como listos. Pendiente: desplegarlos y que SALVIA los valide en producción; Enlace Territorial se valida aparte. | F2: Brayan Marbello / Juan Buitrago | G2: 1 | H2: 46318 | I2: =IF(SUMPRODUCT((Pertenencia!B$2:B$145=1)*(Plan!$D$2:$D$145=3)*(Plan!$J$2:$J$145="Entendimiento"))=0,"",SUMPRODUCT((Pertenencia!B$2:B$145=1)*(Plan!$D$2:$D$145=3)*(Plan!$J$2:$J$145="Entendimiento")*Plan!$E$2:$E$145)/SUMPRODUCT((Pertenencia!B$2:B$145=1)*(Plan!$D$2:$D$145=3)*(Plan!$J$2:$J$145="Entendimiento"))) -> 0.88214286 | J2: =IF(SUMPRODUCT((Pertenencia!B$2:B$145=1)*(Plan!$D$2:$D$145=3)*(Plan!$J$2:$J$145="Construcción y cierre"))=0,"",SUMPRODUCT((Pertenencia!B$2:B$145=1)*(Plan!$D$2:$D$145=3)*(Plan!$J$2:$J$145="Construcción y cierre")*Plan!$E$2:$E$145)/SUMPRODUCT((Pertenencia!B$2:B$145=1)*(Plan!$D$2:$D$145=3)*(Plan!$J$2:$J$145="Construcción y cierre"))) -> 0.58181818 | K2: Módulos contractuales (Anexo Técnico)
A3: M2 | B3: M2 · TAMIZAJE DE FEMINICIDIO | C3: 46218 | D3: =SUMPRODUCT((Pertenencia!C$2:C$145=1)*(Plan!$D$2:$D$145=3)*Plan!$E$2:$E$145)/SUMPRODUCT((Pertenencia!C$2:C$145=1)*(Plan!$D$2:$D$145=3)) -> 0.83181818 | E3: Corte 23-oct: el nuevo Registro V3 está construido en testing (14-oct), con tamizaje, Gestión Salvia, remisión, entidades, barreras y alerta inminente, y pasó QA de punta a punta con Playwright (15-oct, 8 bugs corregidos). Pendiente: nuevo caso sobre registro existente, actualizar caso, ajustes de UI de la supervisión, UAT y paso a main. Avance: Gestión del Conocimiento aprobó el mockup de Reportes, Registro y Alerta Inminente (según el equipo, 13-oct), que incluye el formulario completo del tamizaje de feminicidio con bifurcaciones OSIGD y pareja/no pareja, puntaje y alertas por nivel de riesgo. En producción operan la parametrización de tiempos, la clasificación alto/bajo y la asignación automática. Pendiente: confirmar los rangos del puntaje; el HTML del mockup ya está con el equipo de desarrollo y su paso al servidor de pruebas está prevista para finales de la semana del 13-oct o, a más tardar, a mediados de la semana del 20-oct. Nota: el trabajo del mockup no aparece completo en las horas reportadas; se registra como evidencia en la hoja Trabajo_sin_horas. | F3: Brayan Marbello | G3: 0.55 | H3: 46318 | I3: =IF(SUMPRODUCT((Pertenencia!C$2:C$145=1)*(Plan!$D$2:$D$145=3)*(Plan!$J$2:$J$145="Entendimiento"))=0,"",SUMPRODUCT((Pertenencia!C$2:C$145=1)*(Plan!$D$2:$D$145=3)*(Plan!$J$2:$J$145="Entendimiento")*Plan!$E$2:$E$145)/SUMPRODUCT((Pertenencia!C$2:C$145=1)*(Plan!$D$2:$D$145=3)*(Plan!$J$2:$J$145="Entendimiento"))) -> 0.8875 | J3: =IF(SUMPRODUCT((Pertenencia!C$2:C$145=1)*(Plan!$D$2:$D$145=3)*(Plan!$J$2:$J$145="Construcción y cierre"))=0,"",SUMPRODUCT((Pertenencia!C$2:C$145=1)*(Plan!$D$2:$D$145=3)*(Plan!$J$2:$J$145="Construcción y cierre")*Plan!$E$2:$E$145)/SUMPRODUCT((Pertenencia!C$2:C$145=1)*(Plan!$D$2:$D$145=3)*(Plan!$J$2:$J$145="Construcción y cierre"))) -> 0.68333333 | K3: Módulos contractuales (Anexo Técnico)
A4: M3 | B4: M3 · MEDIDAS DE EMERGENCIA | C4: 46321 | D4: =SUMPRODUCT((Pertenencia!D$2:D$145=1)*(Plan!$D$2:$D$145=3)*Plan!$E$2:$E$145)/SUMPRODUCT((Pertenencia!D$2:D$145=1)*(Plan!$D$2:$D$145=3)) -> 0.35 | E4: Avance: entendimiento documentado en 38 historias de usuario v1.0 (12 grupos, de la remisión a la conclusión, con Cruz Roja y riesgo inminente), que sirven de base al mockup de Medidas de Emergencia; el mockup aprobado de Reportes, Registro y Alerta Inminente ya incluye el formulario de alerta inminente. Pendiente: todo el desarrollo; matriz de campos, lógica de medidas y criterios de aceptación aprobados por el Ministerio. Riesgo: las historias de usuario no cubren familiares ni personas huérfanas (Ley 2530 de 2025). Octubre suma 42 h: 27 h del equipo en los Sprints 19 a 21 y 15 h de gerencia (validación de las historias de usuario y feedback del mockup). El equipo trabajó en las historias de usuario y mockups de Medidas y las primeras pantallas de remisiones de Medidas (PSWYA-849 y 854, en Jira del 22 al 23-oct), además de su adaptación al formulario de seguimiento V4. | F4: Por definir | H4: 46318 | I4: =IF(SUMPRODUCT((Pertenencia!D$2:D$145=1)*(Plan!$D$2:$D$145=3)*(Plan!$J$2:$J$145="Entendimiento"))=0,"",SUMPRODUCT((Pertenencia!D$2:D$145=1)*(Plan!$D$2:$D$145=3)*(Plan!$J$2:$J$145="Entendimiento")*Plan!$E$2:$E$145)/SUMPRODUCT((Pertenencia!D$2:D$145=1)*(Plan!$D$2:$D$145=3)*(Plan!$J$2:$J$145="Entendimiento"))) -> 0.53 | J4: =IF(SUMPRODUCT((Pertenencia!D$2:D$145=1)*(Plan!$D$2:$D$145=3)*(Plan!$J$2:$J$145="Construcción y cierre"))=0,"",SUMPRODUCT((Pertenencia!D$2:D$145=1)*(Plan!$D$2:$D$145=3)*(Plan!$J$2:$J$145="Construcción y cierre")*Plan!$E$2:$E$145)/SUMPRODUCT((Pertenencia!D$2:D$145=1)*(Plan!$D$2:$D$145=3)*(Plan!$J$2:$J$145="Construcción y cierre"))) -> 0.05 | K4: Módulos contractuales (Anexo Técnico)
A5: M4 | B5: M4 · LGBTIQ+ | C5: 46248 | D5: =SUMPRODUCT((Pertenencia!E$2:E$145=1)*(Plan!$D$2:$D$145=3)*Plan!$E$2:$E$145)/SUMPRODUCT((Pertenencia!E$2:E$145=1)*(Plan!$D$2:$D$145=3)) -> 0.825 | E5: Corte 23-oct: las preguntas OSIGD quedaron construidas dentro del Registro V3 en testing. Avance: el mockup aprobado de Reportes, Registro y Alerta Inminente incluye las preguntas OSIGD y el tamizaje diferencial para población LGBTIQ+ dentro del mismo formulario, sin módulo aparte; secciones OSIGHN construidas en psicosocial el 17-sep. Pendiente: construir el MVP en registro y seguimiento; el HTML del mockup ya está con el equipo de desarrollo y su paso al servidor de pruebas está prevista para finales de la semana del 13-oct o, a más tardar, a mediados de la semana del 20-oct. Riesgo: la pregunta OSIGHN aparece hoy donde no corresponde (hallazgo PSI-24). Nota: el trabajo del mockup se registra como evidencia en la hoja Trabajo_sin_horas, sin sumar horas. | F5: Brayan Marbello / Juan Buitrago | G5: 0.01 | H5: 46318 | I5: =IF(SUMPRODUCT((Pertenencia!E$2:E$145=1)*(Plan!$D$2:$D$145=3)*(Plan!$J$2:$J$145="Entendimiento"))=0,"",SUMPRODUCT((Pertenencia!E$2:E$145=1)*(Plan!$D$2:$D$145=3)*(Plan!$J$2:$J$145="Entendimiento")*Plan!$E$2:$E$145)/SUMPRODUCT((Pertenencia!E$2:E$145=1)*(Plan!$D$2:$D$145=3)*(Plan!$J$2:$J$145="Entendimiento"))) -> 0.93333333 | J5: =IF(SUMPRODUCT((Pertenencia!E$2:E$145=1)*(Plan!$D$2:$D$145=3)*(Plan!$J$2:$J$145="Construcción y cierre"))=0,"",SUMPRODUCT((Pertenencia!E$2:E$145=1)*(Plan!$D$2:$D$145=3)*(Plan!$J$2:$J$145="Construcción y cierre")*Plan!$E$2:$E$145)/SUMPRODUCT((Pertenencia!E$2:E$145=1)*(Plan!$D$2:$D$145=3)*(Plan!$J$2:$J$145="Construcción y cierre"))) -> 0.5 | K5: Módulos contractuales (Anexo Técnico)
A6: M5 | B6: M5 · ASP (MODULO WEB) | C6: 46248 | D6: =SUMPRODUCT((Pertenencia!F$2:F$145=1)*(Plan!$D$2:$D$145=3)*Plan!$E$2:$E$145)/SUMPRODUCT((Pertenencia!F$2:F$145=1)*(Plan!$D$2:$D$145=3)) -> 0.68888889 | E6: Corte 23-oct: el formulario ASP de identificación de la víctima quedó construido dentro del Registro V3 en testing. Avance: el mockup aprobado de Reportes, Registro y Alerta Inminente incluye el formulario del módulo web ASP dentro del registro de la víctima. Pendiente: construcción del módulo web; el formulario de registro ya está con el equipo de desarrollo para pasar al servidor de pruebas. Decisión: la solicitud de prórroga del 22-sep pide a la Supervisión definir el tratamiento del desarrollo integral del módulo y su app. Riesgo: los lineamientos de la Dirección de Actividades Sexuales Pagas no se han recibido formalmente. Nota: el trabajo del mockup se registra como evidencia en la hoja Trabajo_sin_horas, sin sumar horas. | F6: Santiago Ramos / Juan Buitrago | G6: 0.18 | H6: 46318 | I6: =IF(SUMPRODUCT((Pertenencia!F$2:F$145=1)*(Plan!$D$2:$D$145=3)*(Plan!$J$2:$J$145="Entendimiento"))=0,"",SUMPRODUCT((Pertenencia!F$2:F$145=1)*(Plan!$D$2:$D$145=3)*(Plan!$J$2:$J$145="Entendimiento")*Plan!$E$2:$E$145)/SUMPRODUCT((Pertenencia!F$2:F$145=1)*(Plan!$D$2:$D$145=3)*(Plan!$J$2:$J$145="Entendimiento"))) -> 0.77857143 | J6: =IF(SUMPRODUCT((Pertenencia!F$2:F$145=1)*(Plan!$D$2:$D$145=3)*(Plan!$J$2:$J$145="Construcción y cierre"))=0,"",SUMPRODUCT((Pertenencia!F$2:F$145=1)*(Plan!$D$2:$D$145=3)*(Plan!$J$2:$J$145="Construcción y cierre")*Plan!$E$2:$E$145)/SUMPRODUCT((Pertenencia!F$2:F$145=1)*(Plan!$D$2:$D$145=3)*(Plan!$J$2:$J$145="Construcción y cierre"))) -> 0.375 | K6: Módulos contractuales (Anexo Técnico)
A7: APP | B7: APP MOVIL MASP (M5) | C7: 46260 | D7: =SUMPRODUCT((Pertenencia!G$2:G$145=1)*(Plan!$D$2:$D$145=3)*Plan!$E$2:$E$145)/SUMPRODUCT((Pertenencia!G$2:G$145=1)*(Plan!$D$2:$D$145=3)) -> 0.485 | E7: Avance: lista de contactos, Home, información de programas y rediseño visual (16-sep); la app apunta al dominio productivo y se subió una nueva versión Android el 23-sep; el informe del 17-sep reporta Seguridad y SOS en Play Store. Pendiente: directorio de entidades, sincronización y bitácora, integración con la Línea 155, App Store, QA y UAT. Decisión: la prórroga solo cubre cerrar lo ya desarrollado, sin pantallas nuevas. | F7: Santiago Ramos | G7: 0.16 | H7: 46318 | I7: =IF(SUMPRODUCT((Pertenencia!G$2:G$145=1)*(Plan!$D$2:$D$145=3)*(Plan!$J$2:$J$145="Entendimiento"))=0,"",SUMPRODUCT((Pertenencia!G$2:G$145=1)*(Plan!$D$2:$D$145=3)*(Plan!$J$2:$J$145="Entendimiento")*Plan!$E$2:$E$145)/SUMPRODUCT((Pertenencia!G$2:G$145=1)*(Plan!$D$2:$D$145=3)*(Plan!$J$2:$J$145="Entendimiento"))) -> 0.65714286 | J7: =IF(SUMPRODUCT((Pertenencia!G$2:G$145=1)*(Plan!$D$2:$D$145=3)*(Plan!$J$2:$J$145="Construcción y cierre"))=0,"",SUMPRODUCT((Pertenencia!G$2:G$145=1)*(Plan!$D$2:$D$145=3)*(Plan!$J$2:$J$145="Construcción y cierre")*Plan!$E$2:$E$145)/SUMPRODUCT((Pertenencia!G$2:G$145=1)*(Plan!$D$2:$D$145=3)*(Plan!$J$2:$J$145="Construcción y cierre"))) -> 0.39230769 | K7: Módulos contractuales (Anexo Técnico)
A8: H06 | B8: ARQUITECTURA EAV-DAG | C8: 46156 | D8: =SUMPRODUCT((Pertenencia!H$2:H$145=1)*(Plan!$D$2:$D$145=3)*Plan!$E$2:$E$145)/SUMPRODUCT((Pertenencia!H$2:H$145=1)*(Plan!$D$2:$D$145=3)) -> 0.905 | E8: Avance: arquitectura EAV-DAG implementada y sosteniendo los módulos en producción. Pendiente: casos migrados con formularios vacíos o sin esquema de seguimiento (SEG-01 y SEG-02), que requieren script en producción. Riesgo: el mecanismo de interoperabilidad con SIVIGE sigue sin definición técnica. | F8: Andres Posada / Andres Ascencio | G8: 1 | H8: 46318 | I8: =IF(SUMPRODUCT((Pertenencia!H$2:H$145=1)*(Plan!$D$2:$D$145=3)*(Plan!$J$2:$J$145="Entendimiento"))=0,"",SUMPRODUCT((Pertenencia!H$2:H$145=1)*(Plan!$D$2:$D$145=3)*(Plan!$J$2:$J$145="Entendimiento")*Plan!$E$2:$E$145)/SUMPRODUCT((Pertenencia!H$2:H$145=1)*(Plan!$D$2:$D$145=3)*(Plan!$J$2:$J$145="Entendimiento"))) -> 0.89444444 | J8: =IF(SUMPRODUCT((Pertenencia!H$2:H$145=1)*(Plan!$D$2:$D$145=3)*(Plan!$J$2:$J$145="Construcción y cierre"))=0,"",SUMPRODUCT((Pertenencia!H$2:H$145=1)*(Plan!$D$2:$D$145=3)*(Plan!$J$2:$J$145="Construcción y cierre")*Plan!$E$2:$E$145)/SUMPRODUCT((Pertenencia!H$2:H$145=1)*(Plan!$D$2:$D$145=3)*(Plan!$J$2:$J$145="Construcción y cierre"))) -> 1 | K8: Hitos transversales
A9: H07 | B9: GOBERNANZA Y GESTION DEL PROYECTO | C9: 46325 | D9: =SUMPRODUCT((Pertenencia!I$2:I$145=1)*(Plan!$D$2:$D$145=3)*Plan!$E$2:$E$145)/SUMPRODUCT((Pertenencia!I$2:I$145=1)*(Plan!$D$2:$D$145=3)) -> 0.87142857 | E9: Avance: solicitud de prórroga hasta el 15-dic radicada el 22-sep, con informe de alcance y riesgos del 17-sep; bitácora de ajustes con 112 ítems, sesiones de revisión con SALVIA y formulario de hallazgos en uso; 3.924 de 5.396 horas ejecutadas a agosto (72,7 %). Pendiente: decisión de la Supervisión sobre la prórroga y el tratamiento de ASP, control de cambios para los nuevos requerimientos y cronograma actualizado. Riesgo: el plazo vigente vence el 26-oct. | F9: Andres Posada | G9: 0.95 | H9: 46318 | I9: =IF(SUMPRODUCT((Pertenencia!I$2:I$145=1)*(Plan!$D$2:$D$145=3)*(Plan!$J$2:$J$145="Entendimiento"))=0,"",SUMPRODUCT((Pertenencia!I$2:I$145=1)*(Plan!$D$2:$D$145=3)*(Plan!$J$2:$J$145="Entendimiento")*Plan!$E$2:$E$145)/SUMPRODUCT((Pertenencia!I$2:I$145=1)*(Plan!$D$2:$D$145=3)*(Plan!$J$2:$J$145="Entendimiento"))) -> 0.87058824 | J9: =IF(SUMPRODUCT((Pertenencia!I$2:I$145=1)*(Plan!$D$2:$D$145=3)*(Plan!$J$2:$J$145="Construcción y cierre"))=0,"",SUMPRODUCT((Pertenencia!I$2:I$145=1)*(Plan!$D$2:$D$145=3)*(Plan!$J$2:$J$145="Construcción y cierre")*Plan!$E$2:$E$145)/SUMPRODUCT((Pertenencia!I$2:I$145=1)*(Plan!$D$2:$D$145=3)*(Plan!$J$2:$J$145="Construcción y cierre"))) -> 0.875 | K9: Hitos transversales
A10: H08 | B10: QA Y PRUEBAS | C10: 46265 | D10: =SUMPRODUCT((Pertenencia!J$2:J$145=1)*(Plan!$D$2:$D$145=3)*Plan!$E$2:$E$145)/SUMPRODUCT((Pertenencia!J$2:J$145=1)*(Plan!$D$2:$D$145=3)) -> 0.32727273 | E10: Corte 23-oct: plan de QA de Registro V3 ejecutado con Playwright (25 casos, 8 bugs corregidos) y pruebas unitarias nuevas en migraciones y estados de caso. Avance: la matriz de hallazgos de SALVIA, con revisión de Kreivo del 8-oct, da por cerrados 107 de 159 hallazgos (29 de 43 en Seguimiento y 78 de 104 en Psicosocial); Rutas sigue con 11 de 12 abiertos desde el 8-sep, aunque el despliegue del 13-oct atiende varios. Pendiente: UAT formal, pruebas de estrés, seguridad y accesibilidad; QA y UAT de la app. Riesgo: las pruebas de punta a punta de Rutas dependen de usuarios y datos de prueba (RUT-17). | F10: Brayan Marbello | G10: 0.65 | H10: 46318 | I10: =IF(SUMPRODUCT((Pertenencia!J$2:J$145=1)*(Plan!$D$2:$D$145=3)*(Plan!$J$2:$J$145="Entendimiento"))=0,"",SUMPRODUCT((Pertenencia!J$2:J$145=1)*(Plan!$D$2:$D$145=3)*(Plan!$J$2:$J$145="Entendimiento")*Plan!$E$2:$E$145)/SUMPRODUCT((Pertenencia!J$2:J$145=1)*(Plan!$D$2:$D$145=3)*(Plan!$J$2:$J$145="Entendimiento"))) | J10: =IF(SUMPRODUCT((Pertenencia!J$2:J$145=1)*(Plan!$D$2:$D$145=3)*(Plan!$J$2:$J$145="Construcción y cierre"))=0,"",SUMPRODUCT((Pertenencia!J$2:J$145=1)*(Plan!$D$2:$D$145=3)*(Plan!$J$2:$J$145="Construcción y cierre")*Plan!$E$2:$E$145)/SUMPRODUCT((Pertenencia!J$2:J$145=1)*(Plan!$D$2:$D$145=3)*(Plan!$J$2:$J$145="Construcción y cierre"))) -> 0.32727273 | K10: Hitos transversales
A11: H09 | B11: DESPLIEGUE EN PRODUCCION | C11: 46326 | D11: =SUMPRODUCT((Pertenencia!K$2:K$145=1)*(Plan!$D$2:$D$145=3)*Plan!$E$2:$E$145)/SUMPRODUCT((Pertenencia!K$2:K$145=1)*(Plan!$D$2:$D$145=3)) -> 0.4 | E11: Corte 23-oct: testing integra los 64 cambios del 13-oct y 29 commits más (PR #117 a #132); main sigue sin cambios desde el 10-sep, así que el despliegue a producción sigue pendiente. Avance: 64 cambios listos para subir a main en el próximo despliegue (corte 13-oct), con lo que se cierra la brecha de main sin cambios desde el 10-sep. En producción: Seguimiento, Barreras, Notificaciones, Tareas y Psicosocial; app Android publicada. Pendiente: ejecutar el despliegue, pasar Rutas a producción con regresión sobre Seguimiento y validar Enlace Territorial, que va aparte. Riesgo: desplegar 64 cambios juntos exige una ventana con respaldo y una ronda de validación con SALVIA. | F11: Camilo Arias | G11: 0.7 | H11: 46318 | I11: =IF(SUMPRODUCT((Pertenencia!K$2:K$145=1)*(Plan!$D$2:$D$145=3)*(Plan!$J$2:$J$145="Entendimiento"))=0,"",SUMPRODUCT((Pertenencia!K$2:K$145=1)*(Plan!$D$2:$D$145=3)*(Plan!$J$2:$J$145="Entendimiento")*Plan!$E$2:$E$145)/SUMPRODUCT((Pertenencia!K$2:K$145=1)*(Plan!$D$2:$D$145=3)*(Plan!$J$2:$J$145="Entendimiento"))) | J11: =IF(SUMPRODUCT((Pertenencia!K$2:K$145=1)*(Plan!$D$2:$D$145=3)*(Plan!$J$2:$J$145="Construcción y cierre"))=0,"",SUMPRODUCT((Pertenencia!K$2:K$145=1)*(Plan!$D$2:$D$145=3)*(Plan!$J$2:$J$145="Construcción y cierre")*Plan!$E$2:$E$145)/SUMPRODUCT((Pertenencia!K$2:K$145=1)*(Plan!$D$2:$D$145=3)*(Plan!$J$2:$J$145="Construcción y cierre"))) -> 0.4 | K11: Hitos transversales
A12: H10 | B12: TRANSFERENCIA DE CONOCIMIENTO | C12: 46326 | D12: =SUMPRODUCT((Pertenencia!L$2:L$145=1)*(Plan!$D$2:$D$145=3)*Plan!$E$2:$E$145)/SUMPRODUCT((Pertenencia!L$2:L$145=1)*(Plan!$D$2:$D$145=3)) -> 0.25416667 | E12: Corte 28-oct: la entidad usa los 15 videos de uso como material de capacitación masiva, a satisfacción, y aceptó parte de ellos para producción (según el equipo). Avance: 15 videos de uso de SALVIA Web (Seguimiento, Barreras y Notificaciones), Mapa de navegación y consolidado de historias de usuario, compartidos con la entidad en agosto; 9 manuales técnicos en PDF (8 de SALVIA Web y 1 de la App MASP) y la Red de acción SALVIA, publicada en el tablero de hitos (19-oct). Pendiente: videos y manuales de usuario de Psicosocial, Medidas, Rutas y Registro, videos de uso de la App, plan de capacitación aprobado, capacitaciones y su validación por SALVIA. Riesgo: 33 de los 100 hallazgos abiertos se resuelven con proceso o entendimiento, lo que indica que la capacitación no debería esperar al final. | F12: Andres Ascencio / Brayan Marbello | G12: 0.4 | H12: 46318 | I12: =IF(SUMPRODUCT((Pertenencia!L$2:L$145=1)*(Plan!$D$2:$D$145=3)*(Plan!$J$2:$J$145="Entendimiento"))=0,"",SUMPRODUCT((Pertenencia!L$2:L$145=1)*(Plan!$D$2:$D$145=3)*(Plan!$J$2:$J$145="Entendimiento")*Plan!$E$2:$E$145)/SUMPRODUCT((Pertenencia!L$2:L$145=1)*(Plan!$D$2:$D$145=3)*(Plan!$J$2:$J$145="Entendimiento"))) | J12: =IF(SUMPRODUCT((Pertenencia!L$2:L$145=1)*(Plan!$D$2:$D$145=3)*(Plan!$J$2:$J$145="Construcción y cierre"))=0,"",SUMPRODUCT((Pertenencia!L$2:L$145=1)*(Plan!$D$2:$D$145=3)*(Plan!$J$2:$J$145="Construcción y cierre")*Plan!$E$2:$E$145)/SUMPRODUCT((Pertenencia!L$2:L$145=1)*(Plan!$D$2:$D$145=3)*(Plan!$J$2:$J$145="Construcción y cierre"))) -> 0.25416667 | K12: Hitos transversales
A13: H11 | B13: ENTREGA CONTRACTUAL Y DERECHOS DE AUTOR | C13: 46325 | D13: =SUMPRODUCT((Pertenencia!M$2:M$145=1)*(Plan!$D$2:$D$145=3)*Plan!$E$2:$E$145)/SUMPRODUCT((Pertenencia!M$2:M$145=1)*(Plan!$D$2:$D$145=3)) -> 0.17307692 | E13: Avance: sin inicio. Pendiente: registro ante la DNDA, publicación final en tiendas y entrega del código fuente; el cronograma propuesto los ubica del 7 al 15-dic. Riesgo: con el plazo vigente al 26-oct no hay ventana para estas actividades si la prórroga no se aprueba. | F13: Andres Posada | G13: 0 | H13: 46318 | I13: =IF(SUMPRODUCT((Pertenencia!M$2:M$145=1)*(Plan!$D$2:$D$145=3)*(Plan!$J$2:$J$145="Entendimiento"))=0,"",SUMPRODUCT((Pertenencia!M$2:M$145=1)*(Plan!$D$2:$D$145=3)*(Plan!$J$2:$J$145="Entendimiento")*Plan!$E$2:$E$145)/SUMPRODUCT((Pertenencia!M$2:M$145=1)*(Plan!$D$2:$D$145=3)*(Plan!$J$2:$J$145="Entendimiento"))) | J13: =IF(SUMPRODUCT((Pertenencia!M$2:M$145=1)*(Plan!$D$2:$D$145=3)*(Plan!$J$2:$J$145="Construcción y cierre"))=0,"",SUMPRODUCT((Pertenencia!M$2:M$145=1)*(Plan!$D$2:$D$145=3)*(Plan!$J$2:$J$145="Construcción y cierre")*Plan!$E$2:$E$145)/SUMPRODUCT((Pertenencia!M$2:M$145=1)*(Plan!$D$2:$D$145=3)*(Plan!$J$2:$J$145="Construcción y cierre"))) -> 0.17307692 | K13: Hitos transversales

Sheet Hitos
A1: No. | B1: HITO | C1: FECHA | D1: ENTREGABLE | E1: ID_ANTERIOR
A2: M1 | B2: M1 · SEGUIMIENTO A LOS CASOS | C2: 46191 | D2: Modulo 1 del Anexo Tecnico. Control y seguimiento de casos por la Linea 155, identificacion de barreras en la ruta de atencion, comunicaciones con entidades y cierre de casos. Incluye Rutas y Barreras y Atencion Psicosocial | E2: H01
A3: M2 | B3: M2 · TAMIZAJE DE FEMINICIDIO | C3: 46218 | D3: Modulo 2 del Anexo Tecnico. Valoracion inicial estructurada del nivel de riesgo de feminicidio con criterios tecnicos estandarizados | E3: H02
A4: M3 | B4: M3 · MEDIDAS DE EMERGENCIA | C4: 46321 | D4: Modulo 3 del Anexo Tecnico. Registro y valoracion estructurada de necesidades de personas en riesgo de feminicidio y de familiares de victimas, para priorizar casos y gestionar intervenciones | E4: Nuevo
A5: M4 | B5: M4 · LGBTIQ+ | C5: 46248 | D5: Modulo 4 del Anexo Tecnico. Profundizar en particularidades, necesidades diferenciadas y abordaje especializado de casos LGBTIQ+ o de violencia por prejuicio | E5: H04
A6: M5 | B6: M5 · ASP (MODULO WEB) | C6: 46248 | D6: Modulo 5 del Anexo Tecnico. Caracterizacion ampliada de personas en actividades sexuales pagas dentro de SALVIA | E6: H03
A7: APP | B7: APP MOVIL MASP (M5) | C7: 46260 | D7: Modulo 5 del Anexo Tecnico. Aplicacion movil para prevencion de violencias en actividades sexuales pagas, con orientacion, rutas de atencion y reporte seguro | E7: H05
A8: H06 | B8: ARQUITECTURA EAV-DAG | C8: 46156 | D8: Nueva arquitectura de datos EAV-DAG implementada, scripts de migracion desde el modelo SOG y diccionario de datos entregado | E8: H06
A9: H07 | B9: GOBERNANZA Y GESTION DEL PROYECTO | C9: 46325 | D9: Plan de gestion del proyecto, matriz de riesgos, comites tecnicos semanales, reportes mensuales y gestion del cambio ejecutados durante todo el contrato | E9: H07
A10: H08 | B10: QA Y PRUEBAS | C10: 46265 | D10: Escenarios de prueba ejecutados: pruebas unitarias, de carga, vulnerabilidad y UAT para SALVIA Web y App MASP con certificacion de la OTI | E10: H08
A11: H09 | B11: DESPLIEGUE EN PRODUCCION | C11: 46326 | D11: Migracion, despliegue de APIs y paso a produccion oficial de SALVIA Web y App MASP con recibo a satisfaccion del Ministerio | E11: H09
A12: H10 | B12: TRANSFERENCIA DE CONOCIMIENTO | C12: 46326 | D12: Manuales de usuario, videos de uso, capacitaciones a funcionarios y listados de asistencia oficiales entregados | E12: H10
A13: H11 | B13: ENTREGA CONTRACTUAL Y DERECHOS DE AUTOR | C13: 46325 | D13: Registro ante DNDA, publicacion oficial en tiendas (Play Store y App Store) y cesion formal del codigo fuente al Ministerio de Igualdad | E13: H11

Sheet Pertenencia
A1: ID | B1: M1 | C1: M2 | D1: M3 | E1: M4 | F1: M5 | G1: APP | H1: H06 | I1: H07 | J1: H08 | K1: H09 | L1: H10 | M1: H11
A2: 1 | B2: 0 | C2: 0 | D2: 0 | E2: 0 | F2: 0 | G2: 0 | H2: 0 | I2: 1 | J2: 0 | K2: 0 | L2: 0 | M2: 0
A3: 1.1 | B3: 0 | C3: 0 | D3: 0 | E3: 0 | F3: 0 | G3: 0 | H3: 0 | I3: 1 | J3: 0 | K3: 0 | L3: 0 | M3: 0
A4: 1.1.1 | B4: 0 | C4: 0 | D4: 0 | E4: 0 | F4: 0 | G4: 0 | H4: 0 | I4: 1 | J4: 0 | K4: 0 | L4: 0 | M4: 0
A5: 1.1.2 | B5: 0 | C5: 0 | D5: 0 | E5: 0 | F5: 0 | G5: 0 | H5: 0 | I5: 1 | J5: 0 | K5: 0 | L5: 0 | M5: 0
A6: 2 | B6: 0 | C6: 0 | D6: 0 | E6: 0 | F6: 1 | G6: 1 | H6: 1 | I6: 1 | J6: 0 | K6: 0 | L6: 0 | M6: 0
A7: 2.1 | B7: 0 | C7: 0 | D7: 0 | E7: 0 | F7: 1 | G7: 0 | H7: 1 | I7: 1 | J7: 0 | K7: 0 | L7: 0 | M7: 0
A8: 2.1.1 | B8: 0 | C8: 0 | D8: 0 | E8: 0 | F8: 0 | G8: 0 | H8: 1 | I8: 1 | J8: 0 | K8: 0 | L8: 0 | M8: 0
A9: 2.1.2 | B9: 0 | C9: 0 | D9: 0 | E9: 0 | F9: 0 | G9: 0 | H9: 0 | I9: 1 | J9: 0 | K9: 0 | L9: 0 | M9: 0
A10: 2.1.3 | B10: 0 | C10: 0 | D10: 0 | E10: 0 | F10: 1 | G10: 0 | H10: 0 | I10: 1 | J10: 0 | K10: 0 | L10: 0 | M10: 0
A11: 2.1.4 | B11: 0 | C11: 0 | D11: 0 | E11: 0 | F11: 0 | G11: 0 | H11: 0 | I11: 1 | J11: 0 | K11: 0 | L11: 0 | M11: 0
A12: 2.2 | B12: 0 | C12: 0 | D12: 0 | E12: 0 | F12: 1 | G12: 1 | H12: 0 | I12: 0 | J12: 0 | K12: 0 | L12: 0 | M12: 0
A13: 2.2.1 | B13: 0 | C13: 0 | D13: 0 | E13: 0 | F13: 0 | G13: 1 | H13: 0 | I13: 0 | J13: 0 | K13: 0 | L13: 0 | M13: 0
... A145: 13.2.1 | B145: 0 | C145: 0 | D145: 0 | E145: 0 | F145: 0 | G145: 0 | H145: 0 | I145: 1 | J145: 0 | K145: 0 | L145: 0 | M145: 0

Sheet Meses
A1: Mes | B1: Etiqueta | C1: Horas_B1 | D1: Horas_B2 | E1: Aspectos_relevantes | F1: Nota
A2: 2026-02 | B2: Feb 2026 | C2: 191 | D2: 0 | E2: Arranque: entendimiento del sistema heredado, auditoría del código y diagnóstico de mejoras urgentes de seguridad. Mockup inicial y primeras historias de usuario del Módulo 1 de Seguimiento. Hojas de vida del equipo entregadas; Gantt y herramienta de control de horas diseñados.
A3: 2026-03 | B3: Mar 2026 | C3: 594 | D3: 0 | E3: Arquitectura EAV-DAG diseñada y adoptada para formularios dinámicos sin alterar el esquema relacional. Requerimientos e historias de usuario de Seguimiento y mapeo del instrumento Kobo/155 al diccionario de datos. Plan de Trabajo v1.0 entregado y cinco mesas técnicas con SALVIA.
A4: 2026-04 | B4: Abr 2026 | C4: 473 | D4: 38 | E4: Primera construcción full-stack de Seguimiento: detalle del caso, timeline, reasignaciones y reporte unificado en Excel. Levantamiento y mockups de Barreras aprobados. Ambiente temporal con CI/CD mientras llegaba el servidor oficial del Ministerio. Primeras 38 horas de la Bolsa 2: requerimientos y flujos de la App MASP.
A5: 2026-05 | B5: May 2026 | C5: 512 | D5: 2.5 | E5: Despliegue en el ambiente de pruebas del Ministerio con CI/CD automatizado. Construcción de Barreras, Notificaciones, Oficios, Tareas, protocolo 3x3 y formulario de cierre. 139 horas de QA y pruebas piloto presenciales con usuarios reales. App firmada y enviada a publicación en Google Play.
A6: 2026-06 | B6: Jun 2026 | C6: 702 | D6: 6 | E6: Salida a producción oficial del módulo de Seguimiento y del Dashboard de KPIs de cinco niveles. Migración de la infraestructura a servidores Linux en AWS y PostgreSQL en RDS, con dominios salvia-colombia.co. Migración de casos activos de riesgo alto y bajo, manual de usuario y primeras capacitaciones presenciales. Nombre identitario (enfoque LGBTIQ+) aplicado en todo el portal.
A7: 2026-07 | B7: Jul 2026 | C7: 290 | D7: 471.5 | E7: Barreras y Notificaciones pasan a producción (9-jul). Construcción del módulo de Atención Psicosocial y del portal de entidades externas. Medidas de Emergencia se pausa por decisión ejecutiva del 6-jul para priorizar Barreras, Rutas y Psicosocial. Solicitud de modificación contractual de horas radicada el 23-jul; la Bolsa 2 registra 471,5 horas en el mes.
A8: 2026-08 | B8: Ago 2026 | C8: 320 | D8: 308 | E8: Actualización de los cuatro formularios de seguimiento y reasignación masiva de unos 3.000 casos. Primera iteración completa de QA del módulo de Atención Psicosocial. Flujos de Rutas y Decisiones del Comité construidos. Matrices de hallazgos unificadas; mapa mental y Gantt de cierre por módulo.
A9: 2026-09 | B9: Sep 2026 | C9: 184.5 | D9: 218 | E9: Atención Psicosocial migrada a producción. Flujo ciudadano Reportar Aquí y Gestión de Reportes construidos. Rutas pasa a pruebas: Mis Acciones Institucionales, Casos Mecanismo y carga masiva de entidades. Acumulado de 4.310,5 horas (79,9 % del contrato) y bitácora única de hallazgos con SALVIA.
A10: 2026-10 | B10: Oct 2026 · corte 23-oct | C10: 288.5 | D10: 180 | E10: Registro V3 construido en testing con QA en Playwright; migración de Alcaldías y 38 entidades con acciones institucionales para el rol entidad. Gestión del Conocimiento aprobó el mockup de Reportes, Registro y Alerta Inminente, que incluye los formularios de tamizaje, LGBTIQ+ y ASP; el HTML ya está con el equipo de desarrollo y su paso al servidor de pruebas está prevista para finales de la semana del 13-oct o, a más tardar, a mediados de la semana del 20-oct. 64 cambios listos para el próximo despliegue a main (corte 13-oct), varios de ellos hallazgos que el equipo no había reportado como resueltos. La matriz de hallazgos de SALVIA da por cerrados 107 de 159 (revisión Kreivo del 8-oct). Solicitud de prórroga hasta el 15-dic radicada el 22-sep, pendiente de decisión. Entendimiento de Reporte y Registro (mockup del 27-sep) y de Medidas de Emergencia (38 historias de usuario). | F10: Corte de avance al 23-oct; incluye los 64 cambios del 13-oct y 29 commits más, todos en testing y aún no desplegados en main ni validados por SALVIA. Horas de octubre: 468.5 h (288.5 h de los Sprints 19 a 21 validadas con Jira y 180 h de gerencia de Andrés Posada del informe INF-SGC-09, que no están en Jira). Las horas del equipo van a Bolsa 1 y las de gerencia a Bolsa 2, por decisión de la gerencia con la discrecionalidad otorgada para usar las bolsas.

Sheet Fichas_Mes
A1: Mes | B1: ID_Hito | C1: Resumen
A2: 2026-02 | B2: M1 | C2: Avance: levantamiento de flujos de proceso enviados por el Ministerio, borrador SRS del Módulo 1 de Seguimiento e integración inicial de Historias de Usuario en el Mockup Dashboard. Pendiente: definición de nuevas tablas relacionales y desarrollo de pantallas operativas. Arquitectura: auditoría del código heredado y levantamiento del diccionario de datos inicial.
A3: 2026-02 | B3: M2 | C3: Avance: redacción de historia de usuario inicial para unificación multicanal de reportes y valoración de riesgo por el Agente Integral. Pendiente: mapeo completo del instrumento Kobo/155 y construcción del motor de reglas.
A4: 2026-02 | B4: H06 | C4: Avance: auditoría técnica del código fuente heredado, diccionario de datos, atributos de tablas, guía de instalación local y diagnóstico de mejoras urgentes de seguridad. Riesgo: alta deuda técnica y acoplamiento en el sistema heredado.
A5: 2026-02 | B5: H07 | C5: Avance: entrega y validación de hojas de vida del equipo, diseño del Gantt y herramienta de control de horas conectada al Dashboard; 191 horas ejecutadas en Bolsa 1 (100% del mes).
A6: 2026-03 | B6: M1 | C6: Avance: levantamiento de requerimientos funcionales y 79 horas de redacción de Historias de Usuario de Seguimiento ancladas a Figma; simulación funcional v4.1 con formulario Kobo y revisión del código actual del módulo. Pendiente: construcción de pantallas Vue y endpoints en Go.
A7: 2026-03 | B7: M2 | C7: Avance: mapeo completo de las preguntas del instrumento actual (Kobo/155) hacia el diccionario de datos (DICCIONARIO_GAD) y definición de reglas de valoración de riesgo Extremo/Alto vs. Moderado/Bajo. Pendiente: implementación del motor DAG en base de datos.
A8: 2026-03 | B8: H06 | C8: Avance: diseño formal de la arquitectura EAV-DAG, propuesta de saneamiento de deuda técnica, revisión de backups y puesta en marcha de la capa DAO y modelos en Go. Decisión: adopción del modelo EAV-DAG sobre tabla pivote para soportar formularios dinámicos sin alterar el esquema relacional.
A9: 2026-03 | B9: H07 | C9: Avance: entrega del Plan de Trabajo v1.0, cronograma Gantt con KPIs por obligación y actas de mesas técnicas de marzo; 785 horas acumuladas a marzo (14,5 % del contrato).
A10: 2026-04 | B10: M1 | C10: Avance: construcción full-stack (Go/GORM + Vue 3) de Detalle del Caso, Detalle de Seguimiento, Mis Seguimientos del Día, Timeline, Reasignaciones y Reporte Unificado Excel (V1+V2); levantamiento y mockups del módulo de Barreras aprobados. Pendiente: pruebas integrales en el servidor oficial del Ministerio.
A11: 2026-04 | B11: M2 | C11: Avance: construcción del motor DAG que procesa el árbol de decisiones del tamizaje y visualización del nivel de riesgo en el detalle del caso. Pendiente: integración con los nuevos formularios dinámicos de seguimiento.
A12: 2026-04 | B12: APP | C12: Avance: 38 horas ejecutadas en Bolsa 2; levantamiento de requerimientos y flujos de navegación con el equipo ASP, diseño de interfaz en Figma y definición de integración con el Core SALVIA. Pendiente: compilación y firma de la primera versión para Google Play Store.
... A34: 2026-08 | B34: H10 | C34: Avance: 15 videos de uso de SALVIA Web (Seguimiento, Barreras y Notificaciones), el Mapa de navegación de SALVIA y el consolidado de historias de usuario, compartidos con la entidad en el cobro de agosto.

Sheet Tareas
A1: Task ID | B1: Nombre_tarea | C1: Item_EDT | D1: Observacion
A2: T-101 | B2: Documentación y Metodología (SALVIA Web) | C2: 4.1.1
A3: T-102 | B3: Documentación y Metodología (App MASP) | C3: 4.2.8
A4: T-103 | B4: Historias de Usuario Actuales | C4: 4.1.2
A5: T-104 | B5: Arquitectura Actual | C5: 4.1.3
A6: T-201 | B6: Presentación, Aprobación y Uso de Mockup Kreivo-Salvia | C6: 2.1.1
A7: T-202 | B7: Firma de Acta de Alcance y SLA | C7: 2.1.2
A8: T-203 | B8: Módulo Web ASP: Variables de Riesgo | C8: 2.1.3
A9: T-204 | B9: App MASP: Diseño de interfaz segura | C9: 2.2.1
A10: T-205 | B10: App MASP: Alertas y Push Notifications | C10: 2.2.2
A11: T-206 | B11: App MASP: Integración con Core SALVIA | C11: 2.2.3
A12: T-207 | B12: Gantt Plan de trabajo Kreivo-Salvia | C12: 2.1.4
A13: T-301 | B13: Diseño y Lógica: Landing Page, Login y Captcha | C13: 3.1.1
... A20: T-403 | B20: Diagramas - Figma y Diccionario de datos | C20: 4.2.3
A21: T-404 | B21: Diagramas - Figma y Diccionario de datos (Bolsa 2) | C21: 4.3.1 | D21: En TimeLogs se usó sobre todo para coordinación de sprints (Bolsa 2)
A22: T-405 | B22: Actas de mesas técnicas | C22: 4.2.4
A23: T-406 | B23: Historias de Usuario - Anclado a Figma | C23: 4.2.5
A24: T-407 | B24: Kobo a Zenkit | C24: 4.2.6
A25: T-408 | B25: Integración Data SOG hacia EAV-DAG | C25: 4.2.7
A26: T-501 | B26: Sprint 1: Setup Entornos, BD y Seguridad | C26: 5.1.1
A27: T-502 | B27: Sprint 2: Módulos de Registro y Motor de Tamizaje | C27: 5.1.2
A28: T-503 | B28: Sprint 3: Dashboard de Trazabilidad y Alertas | C28: 5.1.3
A29: T-504 | B29: Sprint 4: Desarrollo App MASP | C29: 5.2.1
A30: T-505 | B30: Sprint 5: Integración SIVIGE (Interoperabilidad) | C30: 5.1.4 | D30: En TimeLogs incluye backend de Rutas y reasignación masiva, no SIVIGE
A31: T-506 | B31: Ejecución de Pruebas Unitarias y de Carga (sprint) | C31: 5.2.2
A32: T-601 | B32: BI: Diseño de Dashboards y ETL | C32: 6.1.1
A33: T-602 | B33: Adopción: Manuales y Capacitación | C33: 6.1.2
A34: T-603 | B34: Despliegue: Migración a Producción (App) | C34: 6.2.1
A35: T-604 | B35: Soporte: Activación Mesa de Ayuda | C35: 6.2.2
A36: T-605 | B36: Ejecución de Pruebas Unitarias y de Carga (App) | C36: 6.2.3 | D36: En TimeLogs se usó para construir Atención Psicosocial, Rutas y Reportar Aquí (Bolsa 2), no para pruebas de la app
A37: T-606 | B37: Setup Entornos, BD Postgres y Seguridad | C37: 6.1.3
A38: T-607 | B38: Setup Entornos y Seguridad API (App MASP) | C38: 6.2.4
A39: T-608 | B39: Módulos Recepción y Motor de Tamizaje (Web) | C39: 6.1.4
A40: T-609 | B40: Módulo de Seguimiento y Tableros BI / ETL | C40: 6.1.5
A41: T-610 | B41: Desarrollo Interfaz y Lógica App Móvil MASP | C41: 6.2.5 | D41: En TimeLogs incluye mockups de Rutas y modales de Psicosocial
A42: T-702 | B42: Ajustes Post-UAT y Estabilización | C42: 7.2.1
A43: T-703 | B43: Transferencia de Conocimiento y Capacitación | C43: 7.1.2
A44: T-705 | B44: Paso a Producción Oficial SALVIA | C44: 7.1.3
A45: T-707 | B45: QA Unitarias, Carga y Vulnerabilidad (SALVIA Web) | C45: 7.1.5
A46: T-708 | B46: QA Unitarias, Estrés y Vulnerabilidad (App MASP) | C46: 7.2.3
...

Sheet Horas_Jira
A1: Date | B1: Month | C1: Task ID | D1: BOLSA | E1: MODULO | F1: MODULO_SALVIA | G1: Work Description | H1: Hours | I1: Issue | J1: Desarrollador | K1: Sprint | L1: Grupo
A2: 46300 | B2: 10 | C2: J-6.1.11 | D2: Bolsa 1 | E2: Categoría 4: Ingeniería y Desarrollo Web - Macro-Módulo Central (Fase 2) | F2: 6. PSICOSOCIAL (contcto seguro) | G2: Inicio de atención inmediata duplica contactos | H2: 6 | I2: PSWYA-790 | J2: Juan Nicolas Ruiz | K2: Sprint 19 | L2: psico
A3: 46300 | B3: 10 | C3: T-707 | D3: Bolsa 1 | E3: Categoría 8: Aseguramiento de Calidad (QA) y Pruebas Técnicas | F3: 1. ARQUITECTURA | G3: QA de funcionalidades concretadas en sprint 18 | H3: 5 | I3: PSWYA-795 | J3: brayanmarbelo | K3: Sprint 19 | L3: qa
A4: 46300 | B4: 10 | C4: T-1201 | D4: Bolsa 1 | E4: Categoría 1: Gobernanza, Planificación Estratégica y Dirección del Proyecto | F4: 1. ARQUITECTURA | G4: Reunión 5 de octubre: avances de seguimiento | H4: 1 | I4: PSWYA-860 | J4: Andres Felipe Ascencio Medina | K4: Sprint 19 | L4: gestion
A5: 46300 | B5: 10 | C5: T-1201 | D5: Bolsa 1 | E5: Categoría 1: Gobernanza, Planificación Estratégica y Dirección del Proyecto | F5: 1. ARQUITECTURA | G5: Análisis y feedback del sprint del 5 de octubre | H5: 2 | I5: PSWYA-861 | J5: Andres Felipe Ascencio Medina | K5: Sprint 19 | L5: gestion
